
Using device: cpu
Downloading readme: 100%|█████████████████████████████████████| 28.1k/28.1k [00:00<00:00, 13.5MB/s]
Traceback (most recent call last):
  File "/app/train_wb.py", line 274, in <module>
    train_model(config)
  File "/app/train_wb.py", line 186, in train_model
    train_dataloader, val_dataloader, tokenizer_src, tokenizer_tgt = get_ds(config)
  File "/app/train_wb.py", line 141, in get_ds
    ds_raw = load_dataset('opus_books', f"{config['lang_src']}-{config['lang_tgt']}", split='train')
  File "/usr/local/lib/python3.9/site-packages/datasets/load.py", line 2128, in load_dataset
    builder_instance = load_dataset_builder(
  File "/usr/local/lib/python3.9/site-packages/datasets/load.py", line 1814, in load_dataset_builder
    dataset_module = dataset_module_factory(
  File "/usr/local/lib/python3.9/site-packages/datasets/load.py", line 1511, in dataset_module_factory
    raise e1 from None
  File "/usr/local/lib/python3.9/site-packages/datasets/load.py", line 1488, in dataset_module_factory
    return HubDatasetModuleFactoryWithoutScript(
  File "/usr/local/lib/python3.9/site-packages/datasets/load.py", line 1080, in get_module
    builder_configs, default_config_name = create_builder_configs_from_metadata_configs(
  File "/usr/local/lib/python3.9/site-packages/datasets/load.py", line 558, in create_builder_configs_from_metadata_configs
    config_data_files_dict = DataFilesDict.from_patterns(
  File "/usr/local/lib/python3.9/site-packages/datasets/data_files.py", line 686, in from_patterns
    DataFilesList.from_patterns(
  File "/usr/local/lib/python3.9/site-packages/datasets/data_files.py", line 591, in from_patterns
    resolve_pattern(
  File "/usr/local/lib/python3.9/site-packages/datasets/data_files.py", line 353, in resolve_pattern
    for filepath, info in fs.glob(pattern, detail=True).items()
  File "/usr/local/lib/python3.9/site-packages/huggingface_hub/hf_file_system.py", line 521, in glob
    return super().glob(path, **kwargs)
  File "/usr/local/lib/python3.9/site-packages/fsspec/spec.py", line 602, in glob
    allpaths = self.find(root, maxdepth=depth, withdirs=True, detail=True, **kwargs)
  File "/usr/local/lib/python3.9/site-packages/huggingface_hub/hf_file_system.py", line 556, in find
    return super().find(
  File "/usr/local/lib/python3.9/site-packages/fsspec/spec.py", line 493, in find
    out[path] = self.info(path)
  File "/usr/local/lib/python3.9/site-packages/huggingface_hub/hf_file_system.py", line 719, in info
    paths_info = self._api.get_paths_info(
  File "/usr/local/lib/python3.9/site-packages/huggingface_hub/utils/_validators.py", line 114, in _inner_fn
    return fn(*args, **kwargs)
  File "/usr/local/lib/python3.9/site-packages/huggingface_hub/hf_api.py", line 3362, in get_paths_info
    hf_raise_for_status(response)
  File "/usr/local/lib/python3.9/site-packages/huggingface_hub/utils/_http.py", line 482, in hf_raise_for_status
    raise _format(HfHubHTTPError, str(e), response) from e
huggingface_hub.errors.HfHubHTTPError: 429 Client Error: Too Many Requests for url: https://huggingface.co/api/datasets/opus_books/paths-info/1f9f6191d0e91a3c539c2595e2fe48fc1420de9b